import { catchError } from "../../utilities/error.handler.js";

export const getUser = catchError(async (req,res,next)=>{

})

export const updateUser = catchError(async (req,res,next)=>{

})

export const deleteUser = catchError(async (req,res,next)=>{

})

export const getAllUsers = catchError(async (req,res,next)=>{

})

export const deleteAllUsers = catchError(async (req,res,next)=>{

})
